<?xml version="1.0" encoding="utf-8"?>
<!-- =================================================================================== -->
<!-- |    This document was autogenerated by xacro from quadruped_control.urdf         | -->
<!-- |    EDITING THIS FILE BY HAND IS NOT RECOMMENDED                                 | -->
<!-- =================================================================================== -->
<robot name="quadruped_robot">
  <!-- IMU -->
  <gazebo>
    <plugin filename="libgazebo_ros_force.so" name="gazebo_ros_force">
      <bodyName>trunk</bodyName>
      <topicName>/apply_force/trunk</topicName>
    </plugin>
  </gazebo>
  <gazebo reference="imu_link">
    <gravity>true</gravity>
    <sensor name="imu_sensor" type="imu">
      <always_on>true</always_on>
      <update_rate>1000</update_rate>
      <visualize>true</visualize>
      <topic>__default_topic__</topic>
      <plugin filename="libgazebo_ros_imu_sensor.so" name="imu_plugin">
        <topicName>trunk_imu</topicName>
        <bodyName>imu_link</bodyName>
        <updateRateHZ>1000.0</updateRateHZ>
        <gaussianNoise>0.0</gaussianNoise>
        <xyzOffset>0 0 0</xyzOffset>
        <rpyOffset>0 0 0</rpyOffset>
        <frameName>imu_link</frameName>
      </plugin>
      <pose>0 0 0 0 0 0</pose>
    </sensor>
  </gazebo>
  <!-- Foot contacts. -->
  <gazebo reference="right_forward_calf">
    <sensor name="FR_foot_contact" type="contact">
      <update_rate>100</update_rate>
      <plugin filename="libunitreeFootContactPlugin.so" name="contactPlugin"/>
      <contact>
        <collision>FR_calf_fixed_joint_lump__FR_foot_collision_1</collision>
      </contact>
    </sensor>
  </gazebo>
  <gazebo reference="left_forward_calf">
    <sensor name="FL_foot_contact" type="contact">
      <update_rate>100</update_rate>
      <plugin filename="libunitreeFootContactPlugin.so" name="contactPlugin"/>
      <contact>
        <collision>FL_calf_fixed_joint_lump__FL_foot_collision_1</collision>
      </contact>
    </sensor>
  </gazebo>
  <gazebo reference="right_back_calf">
    <sensor name="RR_foot_contact" type="contact">
      <update_rate>100</update_rate>
      <plugin filename="libunitreeFootContactPlugin.so" name="contactPlugin"/>
      <contact>
        <collision>RR_calf_fixed_joint_lump__RR_foot_collision_1</collision>
      </contact>
    </sensor>
  </gazebo>
  <gazebo reference="left_back_calf">
    <sensor name="RL_foot_contact" type="contact">
      <update_rate>100</update_rate>
      <plugin filename="libunitreeFootContactPlugin.so" name="contactPlugin"/>
      <contact>
        <collision>RL_calf_fixed_joint_lump__RL_foot_collision_1</collision>
      </contact>
    </sensor>
  </gazebo>
  <!-- Visualization of Foot contacts. -->
  <gazebo reference="right_forward_foot">
    <visual>
      <plugin filename="libunitreeDrawForcePlugin.so" name="drawForcePlugin">
        <topicName>FR_foot_contact</topicName>
      </plugin>
    </visual>
  </gazebo>
  <gazebo reference="left_forward_foot">
    <visual>
      <plugin filename="libunitreeDrawForcePlugin.so" name="drawForcePlugin">
        <topicName>FL_foot_contact</topicName>
      </plugin>
    </visual>
  </gazebo>
  <gazebo reference="right_back_foot">
    <visual>
      <plugin filename="libunitreeDrawForcePlugin.so" name="drawForcePlugin">
        <topicName>RR_foot_contact</topicName>
      </plugin>
    </visual>
  </gazebo>
  <gazebo reference="left_back_foot">
    <visual>
      <plugin filename="libunitreeDrawForcePlugin.so" name="drawForcePlugin">
        <topicName>RL_foot_contact</topicName>
      </plugin>
    </visual>
  </gazebo>
  <gazebo reference="base">
    <material>Gazebo/Green</material>
    <turnGravityOff>false</turnGravityOff>
  </gazebo>
  <gazebo reference="trunk">
    <mu1>0.2</mu1>
    <mu2>0.2</mu2>
    <kp value="1000000.0"/>
    <kd value="1.0"/>
  </gazebo>
  <gazebo reference="stick_link">
    <mu1>0.2</mu1>
    <mu2>0.2</mu2>
    <material>Gazebo/White</material>
  </gazebo>
  <gazebo reference="imu_link">
    <mu1>0.2</mu1>
    <mu2>0.2</mu2>
    <material>Gazebo/Red</material>
  </gazebo>
  <!-- FL leg -->
  <gazebo reference="left_forward_hip">
    <mu1>0.2</mu1>
    <mu2>0.2</mu2>
    <material>Gazebo/DarkGrey</material>
  </gazebo>
  <gazebo reference="left_forward_thigh">
    <mu1>0.2</mu1>
    <mu2>0.2</mu2>
    <self_collide>1</self_collide>
    <material>Gazebo/DarkGrey</material>
    <kp value="1000000.0"/>
    <kd value="1.0"/>
  </gazebo>
  <gazebo reference="left_forward_calf">
    <mu1>0.2</mu1>
    <mu2>0.2</mu2>
    <self_collide>1</self_collide>
  </gazebo>
  <gazebo reference="left_forward_foot">
    <mu1>0.6</mu1>
    <mu2>0.6</mu2>
    <self_collide>1</self_collide>
    <material>Gazebo/DarkGrey</material>
    <kp value="1000000.0"/>
    <kd value="1.0"/>
  </gazebo>
  <!-- FR leg -->
  <gazebo reference="right_forward_hip">
    <mu1>0.2</mu1>
    <mu2>0.2</mu2>
    <material>Gazebo/DarkGrey</material>
  </gazebo>
  <gazebo reference="right_forward_thigh">
    <mu1>0.2</mu1>
    <mu2>0.2</mu2>
    <self_collide>1</self_collide>
    <material>Gazebo/DarkGrey</material>
    <kp value="1000000.0"/>
    <kd value="1.0"/>
  </gazebo>
  <gazebo reference="right_forward_calf">
    <mu1>0.2</mu1>
    <mu2>0.2</mu2>
    <self_collide>1</self_collide>
  </gazebo>
  <gazebo reference="right_forward_foot">
    <mu1>0.6</mu1>
    <mu2>0.6</mu2>
    <self_collide>1</self_collide>
    <material>Gazebo/DarkGrey</material>
    <kp value="1000000.0"/>
    <kd value="1.0"/>
  </gazebo>
  <!-- RL leg -->
  <gazebo reference="left_back_hip">
    <mu1>0.2</mu1>
    <mu2>0.2</mu2>
    <material>Gazebo/DarkGrey</material>
  </gazebo>
  <gazebo reference="left_back_thigh">
    <mu1>0.2</mu1>
    <mu2>0.2</mu2>
    <self_collide>1</self_collide>
    <material>Gazebo/DarkGrey</material>
    <kp value="1000000.0"/>
    <kd value="1.0"/>
  </gazebo>
  <gazebo reference="left_back_calf">
    <mu1>0.2</mu1>
    <mu2>0.2</mu2>
    <self_collide>1</self_collide>
  </gazebo>
  <gazebo reference="left_back_foot">
    <mu1>0.6</mu1>
    <mu2>0.6</mu2>
    <self_collide>1</self_collide>
    <material>Gazebo/DarkGrey</material>
    <kp value="1000000.0"/>
    <kd value="1.0"/>
  </gazebo>
  <!-- RR leg -->
  <gazebo reference="right_back_hip">
    <mu1>0.2</mu1>
    <mu2>0.2</mu2>
    <material>Gazebo/DarkGrey</material>
  </gazebo>
  <gazebo reference="right_back_thigh">
    <mu1>0.2</mu1>
    <mu2>0.2</mu2>
    <self_collide>1</self_collide>
    <material>Gazebo/DarkGrey</material>
    <kp value="1000000.0"/>
    <kd value="1.0"/>
  </gazebo>
  <gazebo reference="right_back_calf">
    <mu1>0.2</mu1>
    <mu2>0.2</mu2>
    <self_collide>1</self_collide>
  </gazebo>
  <gazebo reference="right_back_foot">
    <mu1>0.6</mu1>
    <mu2>0.6</mu2>
    <self_collide>1</self_collide>
    <material>Gazebo/DarkGrey</material>
    <kp value="1000000.0"/>
    <kd value="1.0"/>
  </gazebo>
  <!-- LEFT FORWARD MOTOR -->
  <!-- RIGHT BACK MOTOR -->
  <!-- Used for fixing robot to Gazebo 'base_link' -->
  <!-- <link name="world"/>
  <joint name="world_body" type="floating">
    <parent link="world"/>
    <child link="body"/>
    <origin rpy="0 0 0" xyz="0 0 0.45"/>
  </joint> -->
  <link name="trunk">
    <inertial>
      <origin rpy="0 0 0" xyz="0.00595967385992909 0.00347011518192815 0.000128724144476447"/>
      <mass value="0.6"/>
      <inertia ixx="0.0" ixy="0.0" ixz="0.0" iyy="0.0" iyz="0.0" izz="0.0"/>
    </inertial>
    <visual>
      <origin rpy="0 0 0" xyz="0 0 0"/>
      <geometry>
        <mesh filename="package://quadruped_robot/meshes/body.STL"/>
      </geometry>
      <material name="">
        <color rgba="0.117647058823529 0.117647058823529 0.117647058823529 1"/>
      </material>
    </visual>
    <collision>
      <origin rpy="0 0 0" xyz="0 0 0"/>
      <geometry>
        <mesh filename="package://quadruped_robot/meshes/body.STL"/>
      </geometry>
    </collision>
  </link>
  <joint name="imu_joint" type="fixed">
    <parent link="trunk"/>
    <child link="imu_link"/>
    <origin rpy="0 0 0" xyz="0 0 0"/>
  </joint>
  <link name="imu_link">
    <inertial>
      <mass value="0.001"/>
      <origin rpy="0 0 0" xyz="0 0 0"/>
      <inertia ixx="0.0001" ixy="0" ixz="0" iyy="0.0001" iyz="0" izz="0.0001"/>
    </inertial>
    <visual>
      <origin rpy="0 0 0" xyz="0 0 0"/>
      <geometry>
        <box size="0.001 0.001 0.001"/>
      </geometry>
      <material name="red"/>
    </visual>
    <collision>
      <origin rpy="0 0 0" xyz="0 0 0"/>
      <geometry>
        <box size=".001 .001 .001"/>
      </geometry>
    </collision>
  </link>
  <link name="left_forward_motor">
    <inertial>
      <origin rpy="0 0 0" xyz="-2.4016E-06 -0.00012687 -0.01825"/>
      <mass value="1.7"/>
      <inertia ixx="0.0011015" ixy="-2.2115E-20" ixz="-4.7092E-20" iyy="0.0011135" iyz="-7.75E-06" izz="0.0018907"/>
    </inertial>
    <visual>
      <origin rpy="0 0 0" xyz="0 0 0"/>
      <geometry>
        <mesh filename="package://quadruped_robot/meshes/left_forward_motor.STL"/>
      </geometry>
      <material name="">
        <color rgba="0.098039 0.098039 0.098039 1"/>
      </material>
    </visual>
    <collision>
      <origin rpy="0 0 0" xyz="0 0 0"/>
      <geometry>
        <mesh filename="package://quadruped_robot/meshes/left_forward_motor.STL"/>
      </geometry>
    </collision>
  </link>
  <joint name="body_left_forward_motor" type="fixed">
    <origin rpy="1.5708 0 0" xyz="0.065 -0.178 0"/>
    <parent link="trunk"/>
    <child link="left_forward_motor"/>
    <axis xyz="0 0 0"/>
  </joint>
  <link name="left_forward_hip">
    <inertial>
      <origin rpy="0 0 0" xyz="-0.00291689067610592 -0.000123327968837258 -0.00111336451391641"/>
      <mass value="1.15"/>
      <inertia ixx="0.00194402199468823" ixy="-7.74995368724056E-06" ixz="2.20326276361798E-11" iyy="0.00113022776843808" iyz="5.94322688269652E-11" izz="0.00115440199269891"/>
    </inertial>
    <visual>
      <origin rpy="0 0 0" xyz="0 0 0"/>
      <geometry>
        <mesh filename="package://quadruped_robot/meshes/left_forward_leg.STL"/>
      </geometry>
      <material name="">
        <color rgba="1 0.937254901960784 0.137254901960784 1"/>
      </material>
    </visual>
    <collision>
      <origin rpy="0 0 0" xyz="0 0 0"/>
      <geometry>
        <mesh filename="package://quadruped_robot/meshes/left_forward_leg.STL"/>
      </geometry>
    </collision>
  </link>
  <joint name="left_forward_hip_joint" type="revolute">
    <origin rpy="0 0 0" xyz="0 0 0.057"/>
    <parent link="left_forward_motor"/>
    <child link="left_forward_hip"/>
    <axis xyz="0 0 -1"/>
    <limit effort="50" lower="-0.78" upper="0.78" velocity="30"/>
    <!-- <dynamics damping = "0.5" friction = "0.1"/> -->
  </joint>
  <link name="left_forward_thigh">
    <inertial>
      <origin rpy="0 0 0" xyz="-0.000122004696831546 -0.0105068917015962 0.0369232159258762"/>
      <mass value="0.3"/>
      <inertia ixx="0.0025944" ixy="2.612E-05" ixz="4.1998E-06" iyy="0.0012986" iyz="1.2724E-05" izz="0.0035306"/>
    </inertial>
    <visual>
      <origin rpy="0 0 0" xyz="0 0 0"/>
      <geometry>
        <mesh filename="package://quadruped_robot/meshes/left_forward_hip.STL"/>
      </geometry>
      <material name="">
        <color rgba="1 0.937254901960784 0.137254901960784 1"/>
      </material>
    </visual>
    <collision>
      <origin rpy="0 0 0" xyz="0 0 0"/>
      <geometry>
        <mesh filename="package://quadruped_robot/meshes/left_forward_hip.STL"/>
      </geometry>
    </collision>
  </link>
  <joint name="left_forward_thigh_joint" type="revolute">
    <origin rpy="0 1.5708 0" xyz="0.01425 0 0"/>
    <parent link="left_forward_hip"/>
    <child link="left_forward_thigh"/>
    <axis xyz="0 0 -1"/>
    <limit effort="50" lower="-1.31" upper="1.31" velocity="30"/>
    <!-- <dynamics damping = "0.5" friction = "0.1"/> -->
  </joint>
  <link name="left_forward_calf">
    <inertial>
      <origin rpy="0 0 0" xyz="1.33042839911279E-05 0.0735129471212146 1.01143462072351E-05"/>
      <mass value="0.1"/>
      <inertia ixx="0.0" ixy="0.0" ixz="0.0" iyy="0.0" iyz="0.0" izz="0.0"/>
    </inertial>
    <visual>
      <origin rpy="0 0 0" xyz="0 0 0"/>
      <geometry>
        <mesh filename="package://quadruped_robot/meshes/left_forward_calf.STL"/>
      </geometry>
      <material name="">
        <color rgba="0.101960784313725 0.101960784313725 0.101960784313725 1"/>
      </material>
    </visual>
    <collision>
      <origin rpy="0 0 0" xyz="0 0 0"/>
      <geometry>
        <mesh filename="package://quadruped_robot/meshes/left_forward_calf.STL"/>
      </geometry>
    </collision>
  </link>
  <joint name="left_forward_calf_joint" type="revolute">
    <origin rpy="0 0 3.1416" xyz="0 -0.208 0.068"/>
    <parent link="left_forward_thigh"/>
    <child link="left_forward_calf"/>
    <axis xyz="0 0 -1"/>
    <limit effort="50" lower="-2.6" upper="2.6" velocity="30"/>
    <!-- <dynamics damping = "0.5" friction = "0.1"/> -->
  </joint>
  <link name="left_forward_foot">
    <inertial>
      <origin rpy="0 0 0" xyz="2.69840204902838E-07 -0.0143807852672446 -1.27049741839858E-05"/>
      <mass value="0.04"/>
      <!-- <mass
        value="50" /> -->
      <inertia ixx="1.41888786495424E-05" ixy="-2.90568059491003E-10" ixz="-4.06238332327928E-11" iyy="8.65121074865133E-06" iyz="3.97669015260362E-09" izz="1.41178031393142E-05"/>
    </inertial>
    <visual>
      <origin rpy="0 0 0" xyz="0 0 0"/>
      <geometry>
        <mesh filename="package://quadruped_robot/meshes/left_forward_foot.STL"/>
      </geometry>
      <material name="">
        <color rgba="0.298039215686275 0.298039215686275 0.298039215686275 1"/>
      </material>
    </visual>
    <collision>
      <origin rpy="0 0 0" xyz="0 0 0"/>
      <geometry>
        <mesh filename="package://quadruped_robot/meshes/left_forward_foot.STL"/>
      </geometry>
    </collision>
  </link>
  <joint name="left_forward_foot_fixed" type="fixed">
    <origin rpy="0 0 3.1416" xyz="0 0.1775 0"/>
    <parent link="left_forward_calf"/>
    <child link="left_forward_foot"/>
    <axis xyz="0 0 0"/>
  </joint>
  <dynamics friction="1000"/>
  <!-- RIGHT BACK LEG -->
  <link name="right_back_motor">
    <inertial>
      <origin rpy="0 0 0" xyz="-2.4016E-06 -0.00012687 -0.01825"/>
      <mass value="1.7"/>
      <inertia ixx="0.0011015" ixy="-2.2115E-20" ixz="-4.7092E-20" iyy="0.0011135" iyz="-7.75E-06" izz="0.0018907"/>
    </inertial>
    <visual>
      <origin rpy="0 0 0" xyz="0 0 0"/>
      <geometry>
        <mesh filename="package://quadruped_robot/meshes/left_forward_motor.STL"/>
      </geometry>
      <material name="">
        <color rgba="0.098039 0.098039 0.098039 1"/>
      </material>
    </visual>
    <collision>
      <origin rpy="0 0 0" xyz="0 0 0"/>
      <geometry>
        <mesh filename="package://quadruped_robot/meshes/left_forward_motor.STL"/>
      </geometry>
    </collision>
  </link>
  <joint name="body_right_back_motor" type="fixed">
    <origin rpy="1.5708 0 3.1416" xyz="-0.065 0.178 0"/>
    <parent link="trunk"/>
    <child link="right_back_motor"/>
    <axis xyz="0 0 0"/>
  </joint>
  <link name="right_back_hip">
    <inertial>
      <origin rpy="0 0 0" xyz="-0.00291689067610592 -0.000123327968837258 -0.00111336451391641"/>
      <mass value="1.15"/>
      <inertia ixx="0.00194402199468823" ixy="-7.74995368724056E-06" ixz="2.20326276361798E-11" iyy="0.00113022776843808" iyz="5.94322688269652E-11" izz="0.00115440199269891"/>
    </inertial>
    <visual>
      <origin rpy="0 0 0" xyz="0 0 0"/>
      <geometry>
        <mesh filename="package://quadruped_robot/meshes/left_forward_leg.STL"/>
      </geometry>
      <material name="">
        <color rgba="1 0.937254901960784 0.137254901960784 1"/>
      </material>
    </visual>
    <collision>
      <origin rpy="0 0 0" xyz="0 0 0"/>
      <geometry>
        <mesh filename="package://quadruped_robot/meshes/left_forward_leg.STL"/>
      </geometry>
    </collision>
  </link>
  <joint name="right_back_hip_joint" type="revolute">
    <origin rpy="0 0 0" xyz="0 0 0.057"/>
    <parent link="right_back_motor"/>
    <child link="right_back_hip"/>
    <axis xyz="0 0 -1"/>
    <limit effort="50" lower="-0.78" upper="0.78" velocity="30"/>
    <!-- <dynamics damping = "0.5" friction = "0.1"/> -->
  </joint>
  <link name="right_back_thigh">
    <inertial>
      <origin rpy="0 0 0" xyz="-0.000122004696831546 -0.0105068917015962 0.0369232159258762"/>
      <mass value="0.3"/>
      <inertia ixx="0.0025944" ixy="2.612E-05" ixz="4.1998E-06" iyy="0.0012986" iyz="1.2724E-05" izz="0.0035306"/>
    </inertial>
    <visual>
      <origin rpy="0 0 0" xyz="0 0 0"/>
      <geometry>
        <mesh filename="package://quadruped_robot/meshes/left_forward_hip.STL"/>
      </geometry>
      <material name="">
        <color rgba="1 0.937254901960784 0.137254901960784 1"/>
      </material>
    </visual>
    <collision>
      <origin rpy="0 0 0" xyz="0 0 0"/>
      <geometry>
        <mesh filename="package://quadruped_robot/meshes/left_forward_hip.STL"/>
      </geometry>
    </collision>
  </link>
  <joint name="right_back_thigh_joint" type="revolute">
    <origin rpy="0 1.5708 0" xyz="0.01425 0 0"/>
    <parent link="right_back_hip"/>
    <child link="right_back_thigh"/>
    <axis xyz="0 0 -1"/>
    <limit effort="50" lower="-1.31" upper="1.31" velocity="30"/>
    <!-- <dynamics damping = "0.5" friction = "0.1"/> -->
  </joint>
  <link name="right_back_calf">
    <inertial>
      <origin rpy="0 0 0" xyz="1.33042839911279E-05 0.0735129471212146 1.01143462072351E-05"/>
      <mass value="0.1"/>
      <inertia ixx="0.0" ixy="0.0" ixz="0.0" iyy="0.0" iyz="0.0" izz="0.0"/>
    </inertial>
    <visual>
      <origin rpy="0 0 0" xyz="0 0 0"/>
      <geometry>
        <mesh filename="package://quadruped_robot/meshes/left_forward_calf.STL"/>
      </geometry>
      <material name="">
        <color rgba="0.101960784313725 0.101960784313725 0.101960784313725 1"/>
      </material>
    </visual>
    <collision>
      <origin rpy="0 0 0" xyz="0 0 0"/>
      <geometry>
        <mesh filename="package://quadruped_robot/meshes/left_forward_calf.STL"/>
      </geometry>
    </collision>
  </link>
  <joint name="right_back_calf_joint" type="revolute">
    <origin rpy="0 0 3.1416" xyz="0 -0.208 0.068"/>
    <parent link="right_back_thigh"/>
    <child link="right_back_calf"/>
    <axis xyz="0 0 -1"/>
    <limit effort="50" lower="-2.6" upper="2.6" velocity="30"/>
    <!-- <dynamics damping = "0.5" friction = "0.1"/> -->
  </joint>
  <link name="right_back_foot">
    <inertial>
      <origin rpy="0 0 0" xyz="2.69840204902838E-07 -0.0143807852672446 -1.27049741839858E-05"/>
      <mass value="0.04"/>
      <!-- <mass
        value="50" /> -->
      <inertia ixx="1.41888786495424E-05" ixy="-2.90568059491003E-10" ixz="-4.06238332327928E-11" iyy="8.65121074865133E-06" iyz="3.97669015260362E-09" izz="1.41178031393142E-05"/>
    </inertial>
    <visual>
      <origin rpy="0 0 0" xyz="0 0 0"/>
      <geometry>
        <mesh filename="package://quadruped_robot/meshes/left_forward_foot.STL"/>
      </geometry>
      <material name="">
        <color rgba="0.298039215686275 0.298039215686275 0.298039215686275 1"/>
      </material>
    </visual>
    <collision>
      <origin rpy="0 0 0" xyz="0 0 0"/>
      <geometry>
        <mesh filename="package://quadruped_robot/meshes/left_forward_foot.STL"/>
      </geometry>
    </collision>
  </link>
  <joint name="right_back_foot_fixed" type="fixed">
    <origin rpy="0 0 3.1416" xyz="0 0.1775 0"/>
    <parent link="right_back_calf"/>
    <child link="right_back_foot"/>
    <axis xyz="0 0 0"/>
  </joint>
  <dynamics friction="1000"/>
  <!-- LEFT BACK LEG -->
  <link name="left_back_motor">
    <inertial>
      <origin rpy="0 0 0" xyz="2.4016E-06 0.00012687 -0.01825"/>
      <mass value="1.7"/>
      <inertia ixx="0.0011015" ixy="-2.2115E-20" ixz="-4.7092E-20" iyy="0.0011135" iyz="-7.75E-06" izz="0.0018907"/>
    </inertial>
    <visual>
      <origin rpy="0 0 0" xyz="0 0 0"/>
      <geometry>
        <mesh filename="package://quadruped_robot/meshes/left_back_motor.STL"/>
      </geometry>
      <material name="">
        <color rgba="0.098039 0.098039 0.098039 1"/>
      </material>
    </visual>
    <collision>
      <origin rpy="0 0 0" xyz="0 0 0"/>
      <geometry>
        <mesh filename="package://quadruped_robot/meshes/left_back_motor.STL"/>
      </geometry>
    </collision>
  </link>
  <joint name="body_left_back_motor" type="fixed">
    <origin rpy="-1.5707963267949 0 0" xyz="0.065 0.178 0"/>
    <parent link="trunk"/>
    <child link="left_back_motor"/>
    <axis xyz="0 0 0"/>
  </joint>
  <link name="left_back_hip">
    <inertial>
      <origin rpy="0 0 0" xyz="-0.0029169 0.00012334 -0.001118"/>
      <mass value="1.15"/>
      <inertia ixx="0.00194402199468823" ixy="-7.74995368724056E-06" ixz="2.20326276361798E-11" iyy="0.00113022776843808" iyz="5.94322688269652E-11" izz="0.00115440199269891"/>
    </inertial>
    <visual>
      <origin rpy="0 0 0" xyz="0 0 0"/>
      <geometry>
        <mesh filename="package://quadruped_robot/meshes/left_back_leg.STL"/>
      </geometry>
      <material name="">
        <color rgba="1 0.93725 0.13725 1"/>
      </material>
    </visual>
    <collision>
      <origin rpy="0 0 0" xyz="0 0 0"/>
      <geometry>
        <mesh filename="package://quadruped_robot/meshes/left_back_leg.STL"/>
      </geometry>
    </collision>
  </link>
  <joint name="left_back_hip_joint" type="revolute">
    <origin rpy="0 0 0" xyz="0 0 0.057"/>
    <parent link="left_back_motor"/>
    <child link="left_back_hip"/>
    <axis xyz="0 0 -1"/>
    <limit effort="50" lower="-0.78" upper="0.78" velocity="30"/>
    <!-- <dynamics damping = "0.5" friction = "0.1"/> -->
  </joint>
  <link name="left_back_thigh">
    <inertial>
      <origin rpy="0 0 0" xyz="-0.00011894 0.010505 0.036923"/>
      <mass value="0.3"/>
      <inertia ixx="0.0025944" ixy="2.612E-05" ixz="4.1998E-06" iyy="0.0012986" iyz="1.2724E-05" izz="0.0035306"/>
    </inertial>
    <visual>
      <origin rpy="0 0 0" xyz="0 0 0"/>
      <geometry>
        <mesh filename="package://quadruped_robot/meshes/left_back_hip.STL"/>
      </geometry>
      <material name="">
        <color rgba="1 0.93725 0.13725 1"/>
      </material>
    </visual>
    <collision>
      <origin rpy="0 0 0" xyz="0 0 0"/>
      <geometry>
        <mesh filename="package://quadruped_robot/meshes/left_back_hip.STL"/>
      </geometry>
    </collision>
  </link>
  <joint name="left_back_thigh_joint" type="revolute">
    <origin rpy="0 1.5708 0" xyz="0.01425 0 0"/>
    <parent link="left_back_hip"/>
    <child link="left_back_thigh"/>
    <axis xyz="0 0 -1"/>
    <limit effort="50" lower="-1.31" upper="1.31" velocity="30"/>
    <!-- <dynamics damping = "0.5" friction = "0.1"/> -->
  </joint>
  <link name="left_back_calf">
    <inertial>
      <origin rpy="0 0 0" xyz="0.003150209581748 0.0608714249947071 0.0130084906327194"/>
      <mass value="0.1"/>
      <inertia ixx="0.0" ixy="0.0" ixz="0.0" iyy="0.0" iyz="0.0" izz="0.0"/>
    </inertial>
    <visual>
      <origin rpy="0 0 0" xyz="0 0 0"/>
      <geometry>
        <mesh filename="package://quadruped_robot/meshes/left_back_calf.STL"/>
      </geometry>
      <material name="">
        <color rgba="0.101960784313725 0.101960784313725 0.101960784313725 1"/>
      </material>
    </visual>
    <collision>
      <origin rpy="0 0 0" xyz="0 0 0"/>
      <geometry>
        <mesh filename="package://quadruped_robot/meshes/left_back_calf.STL"/>
      </geometry>
    </collision>
  </link>
  <joint name="left_back_calf_joint" type="revolute">
    <origin rpy="0 0 0" xyz="-0.003139 0.20789 0.055"/>
    <parent link="left_back_thigh"/>
    <child link="left_back_calf"/>
    <axis xyz="0 0 -1"/>
    <limit effort="50" lower="-2.6" upper="2.6" velocity="30"/>
    <!-- <dynamics damping = "0.5" friction = "0.1"/> -->
  </joint>
  <link name="left_back_foot">
    <inertial>
      <origin rpy="0 0 0" xyz="2.67734406894649E-07 -0.0143807830353894 -1.27018434094295E-05"/>
      <mass value="0.04"/>
      <!-- <mass
        value="50" /> -->
      <inertia ixx="1.41888786495424E-05" ixy="-2.90568059491003E-10" ixz="-4.06238332327928E-11" iyy="8.65121074865133E-06" iyz="3.97669015260362E-09" izz="1.41178031393142E-05"/>
    </inertial>
    <visual>
      <origin rpy="0 0 0" xyz="0 0 0"/>
      <geometry>
        <mesh filename="package://quadruped_robot/meshes/left_back_foot.STL"/>
      </geometry>
      <material name="">
        <color rgba="0.298039215686275 0.298039215686275 0.298039215686275 1"/>
      </material>
    </visual>
    <collision>
      <origin rpy="0 0 0" xyz="0 0 0"/>
      <geometry>
        <mesh filename="package://quadruped_robot/meshes/left_back_foot.STL"/>
      </geometry>
    </collision>
  </link>
  <joint name="left_back_foot_fixed" type="fixed">
    <origin rpy="0 0 3.1416" xyz="0.003139 0.17761 0.013"/>
    <parent link="left_back_calf"/>
    <child link="left_back_foot"/>
    <axis xyz="0 0 0"/>
    <dynamics friction="1000"/>
  </joint>
  <!-- RIGHT FORWARD LEG -->
  <link name="right_forward_motor">
    <inertial>
      <origin rpy="0 0 0" xyz="2.4016E-06 0.00012687 -0.01825"/>
      <mass value="1.7"/>
      <inertia ixx="0.0011015" ixy="-2.2115E-20" ixz="-4.7092E-20" iyy="0.0011135" iyz="-7.75E-06" izz="0.0018907"/>
    </inertial>
    <visual>
      <origin rpy="0 0 0" xyz="0 0 0"/>
      <geometry>
        <mesh filename="package://quadruped_robot/meshes/left_back_motor.STL"/>
      </geometry>
      <material name="">
        <color rgba="0.098039 0.098039 0.098039 1"/>
      </material>
    </visual>
    <collision>
      <origin rpy="0 0 0" xyz="0 0 0"/>
      <geometry>
        <mesh filename="package://quadruped_robot/meshes/left_back_motor.STL"/>
      </geometry>
    </collision>
  </link>
  <joint name="body_right_forward_motor" type="fixed">
    <origin rpy="-1.5707963267949 0 3.1416" xyz="-0.065 -0.178 0"/>
    <parent link="trunk"/>
    <child link="right_forward_motor"/>
    <axis xyz="0 0 0"/>
  </joint>
  <link name="right_forward_hip">
    <inertial>
      <origin rpy="0 0 0" xyz="-0.0029169 0.00012334 -0.001118"/>
      <mass value="1.15"/>
      <inertia ixx="0.00194402199468823" ixy="-7.74995368724056E-06" ixz="2.20326276361798E-11" iyy="0.00113022776843808" iyz="5.94322688269652E-11" izz="0.00115440199269891"/>
    </inertial>
    <visual>
      <origin rpy="0 0 0" xyz="0 0 0"/>
      <geometry>
        <mesh filename="package://quadruped_robot/meshes/left_back_leg.STL"/>
      </geometry>
      <material name="">
        <color rgba="1 0.93725 0.13725 1"/>
      </material>
    </visual>
    <collision>
      <origin rpy="0 0 0" xyz="0 0 0"/>
      <geometry>
        <mesh filename="package://quadruped_robot/meshes/left_back_leg.STL"/>
      </geometry>
    </collision>
  </link>
  <joint name="right_forward_hip_joint" type="revolute">
    <origin rpy="0 0 0" xyz="0 0 0.057"/>
    <parent link="right_forward_motor"/>
    <child link="right_forward_hip"/>
    <axis xyz="0 0 -1"/>
    <limit effort="50" lower="-0.78" upper="0.78" velocity="30"/>
    <!-- <dynamics damping = "0.5" friction = "0.1"/> -->
  </joint>
  <link name="right_forward_thigh">
    <inertial>
      <origin rpy="0 0 0" xyz="-0.00011894 0.010505 0.036923"/>
      <mass value="0.3"/>
      <inertia ixx="0.0025944" ixy="2.612E-05" ixz="4.1998E-06" iyy="0.0012986" iyz="1.2724E-05" izz="0.0035306"/>
    </inertial>
    <visual>
      <origin rpy="0 0 0" xyz="0 0 0"/>
      <geometry>
        <mesh filename="package://quadruped_robot/meshes/left_back_hip.STL"/>
      </geometry>
      <material name="">
        <color rgba="1 0.93725 0.13725 1"/>
      </material>
    </visual>
    <collision>
      <origin rpy="0 0 0" xyz="0 0 0"/>
      <geometry>
        <mesh filename="package://quadruped_robot/meshes/left_back_hip.STL"/>
      </geometry>
    </collision>
  </link>
  <joint name="right_forward_thigh_joint" type="revolute">
    <origin rpy="0 1.5708 0" xyz="0.01425 0 0"/>
    <parent link="right_forward_hip"/>
    <child link="right_forward_thigh"/>
    <axis xyz="0 0 -1"/>
    <limit effort="50" lower="-1.31" upper="1.31" velocity="30"/>
    <!-- <dynamics damping = "0.5" friction = "0.1"/> -->
  </joint>
  <link name="right_forward_calf">
    <inertial>
      <origin rpy="0 0 0" xyz="0.003150209581748 0.0608714249947071 0.0130084906327194"/>
      <mass value="0.1"/>
      <inertia ixx="0.0" ixy="0.0" ixz="0.0" iyy="0.0" iyz="0.0" izz="0.0"/>
    </inertial>
    <visual>
      <origin rpy="0 0 0" xyz="0 0 0"/>
      <geometry>
        <mesh filename="package://quadruped_robot/meshes/left_back_calf.STL"/>
      </geometry>
      <material name="">
        <color rgba="0.101960784313725 0.101960784313725 0.101960784313725 1"/>
      </material>
    </visual>
    <collision>
      <origin rpy="0 0 0" xyz="0 0 0"/>
      <geometry>
        <mesh filename="package://quadruped_robot/meshes/left_back_calf.STL"/>
      </geometry>
    </collision>
  </link>
  <joint name="right_forward_calf_joint" type="revolute">
    <origin rpy="0 0 0" xyz="-0.003139 0.20789 0.055"/>
    <parent link="right_forward_thigh"/>
    <child link="right_forward_calf"/>
    <axis xyz="0 0 -1"/>
    <limit effort="50" lower="-2.6" upper="2.6" velocity="30"/>
    <!-- <dynamics damping = "0.5" friction = "0.1"/> -->
  </joint>
  <link name="right_forward_foot">
    <inertial>
      <origin rpy="0 0 0" xyz="2.67734406894649E-07 -0.0143807830353894 -1.27018434094295E-05"/>
      <mass value="0.04"/>
      <!-- <mass
        value="50" /> -->
      <inertia ixx="1.41888786495424E-05" ixy="-2.90568059491003E-10" ixz="-4.06238332327928E-11" iyy="8.65121074865133E-06" iyz="3.97669015260362E-09" izz="1.41178031393142E-05"/>
    </inertial>
    <visual>
      <origin rpy="0 0 0" xyz="0 0 0"/>
      <geometry>
        <mesh filename="package://quadruped_robot/meshes/left_back_foot.STL"/>
      </geometry>
      <material name="">
        <color rgba="0.298039215686275 0.298039215686275 0.298039215686275 1"/>
      </material>
    </visual>
    <collision>
      <origin rpy="0 0 0" xyz="0 0 0"/>
      <geometry>
        <mesh filename="package://quadruped_robot/meshes/left_back_foot.STL"/>
      </geometry>
    </collision>
  </link>
  <joint name="right_forward_foot_fixed" type="fixed">
    <origin rpy="0 0 3.1416" xyz="0.003139 0.17761 0.013"/>
    <parent link="right_forward_calf"/>
    <child link="right_forward_foot"/>
    <axis xyz="0 0 0"/>
    <dynamics friction="1000"/>
  </joint>
  <transmission name="tran0">
    <type>transmission_interface/SimpleTransmission</type>
    <joint name="right_forward_hip_joint">
      <hardwareInterface>hardware_interface/EffortJointInterface</hardwareInterface>
    </joint>
    <actuator name="FR_hip_motor">
      <hardwareInterface>hardware_interface/EffortJointInterface</hardwareInterface>
      <!--hardware_interface/-->
      <mechanicalReduction>9</mechanicalReduction>
    </actuator>
  </transmission>
  <transmission name="tran1">
    <type>transmission_interface/SimpleTransmission</type>
    <joint name="right_forward_thigh_joint">
      <hardwareInterface>hardware_interface/EffortJointInterface</hardwareInterface>
    </joint>
    <actuator name="FR_thigh_motor">
      <hardwareInterface>hardware_interface/EffortJointInterface</hardwareInterface>
      <!--hardware_interface/-->
      <mechanicalReduction>9</mechanicalReduction>
    </actuator>
  </transmission>
  <transmission name="tran2">
    <type>transmission_interface/SimpleTransmission</type>
    <joint name="right_forward_calf_joint">
      <hardwareInterface>hardware_interface/EffortJointInterface</hardwareInterface>
    </joint>
    <actuator name="FR_calf_motor">
      <hardwareInterface>hardware_interface/EffortJointInterface</hardwareInterface>
      <!--hardware_interface/-->
      <mechanicalReduction>6</mechanicalReduction>
    </actuator>
  </transmission>
  <transmission name="tran3">
    <type>transmission_interface/SimpleTransmission</type>
    <joint name="left_forward_hip_joint">
      <hardwareInterface>hardware_interface/EffortJointInterface</hardwareInterface>
    </joint>
    <actuator name="FL_hip_motor">
      <hardwareInterface>hardware_interface/EffortJointInterface</hardwareInterface>
      <!--hardware_interface/-->
      <mechanicalReduction>9</mechanicalReduction>
    </actuator>
  </transmission>
  <transmission name="tran4">
    <type>transmission_interface/SimpleTransmission</type>
    <joint name="left_forward_thigh_joint">
      <hardwareInterface>hardware_interface/EffortJointInterface</hardwareInterface>
    </joint>
    <actuator name="FL_thigh_motor">
      <hardwareInterface>hardware_interface/EffortJointInterface</hardwareInterface>
      <!--hardware_interface/-->
      <mechanicalReduction>9</mechanicalReduction>
    </actuator>
  </transmission>
  <transmission name="tran5">
    <type>transmission_interface/SimpleTransmission</type>
    <joint name="left_forward_calf_joint">
      <hardwareInterface>hardware_interface/EffortJointInterface</hardwareInterface>
    </joint>
    <actuator name="FL_calf_motor">
      <hardwareInterface>hardware_interface/EffortJointInterface</hardwareInterface>
      <!--hardware_interface/-->
      <mechanicalReduction>6</mechanicalReduction>
    </actuator>
  </transmission>
  <transmission name="tran6">
    <type>transmission_interface/SimpleTransmission</type>
    <joint name="right_back_hip_joint">
      <hardwareInterface>hardware_interface/EffortJointInterface</hardwareInterface>
    </joint>
    <actuator name="RR_hip_motor">
      <hardwareInterface>hardware_interface/EffortJointInterface</hardwareInterface>
      <!--hardware_interface/-->
      <mechanicalReduction>9</mechanicalReduction>
    </actuator>
  </transmission>
  <transmission name="tran7">
    <type>transmission_interface/SimpleTransmission</type>
    <joint name="right_back_thigh_joint">
      <hardwareInterface>hardware_interface/EffortJointInterface</hardwareInterface>
    </joint>
    <actuator name="RR_thigh_motor">
      <hardwareInterface>hardware_interface/EffortJointInterface</hardwareInterface>
      <!--hardware_interface/-->
      <mechanicalReduction>9</mechanicalReduction>
    </actuator>
  </transmission>
  <transmission name="tran8">
    <type>transmission_interface/SimpleTransmission</type>
    <joint name="right_back_calf_joint">
      <hardwareInterface>hardware_interface/EffortJointInterface</hardwareInterface>
    </joint>
    <actuator name="RR_calf_motor">
      <hardwareInterface>hardware_interface/EffortJointInterface</hardwareInterface>
      <!--hardware_interface/-->
      <mechanicalReduction>6</mechanicalReduction>
    </actuator>
  </transmission>
  <transmission name="tran9">
    <type>transmission_interface/SimpleTransmission</type>
    <joint name="left_back_hip_joint">
      <hardwareInterface>hardware_interface/EffortJointInterface</hardwareInterface>
    </joint>
    <actuator name="RL_hip_motor">
      <hardwareInterface>hardware_interface/EffortJointInterface</hardwareInterface>
      <!--hardware_interface/-->
      <mechanicalReduction>9</mechanicalReduction>
    </actuator>
  </transmission>
  <transmission name="tran10">
    <type>transmission_interface/SimpleTransmission</type>
    <joint name="left_back_thigh_joint">
      <hardwareInterface>hardware_interface/EffortJointInterface</hardwareInterface>
    </joint>
    <actuator name="RL_thigh_motor">
      <hardwareInterface>hardware_interface/EffortJointInterface</hardwareInterface>
      <!--hardware_interface/-->
      <mechanicalReduction>9</mechanicalReduction>
    </actuator>
  </transmission>
  <transmission name="tran11">
    <type>transmission_interface/SimpleTransmission</type>
    <joint name="left_back_calf_joint">
      <hardwareInterface>hardware_interface/EffortJointInterface</hardwareInterface>
    </joint>
    <actuator name="RL_calf_motor">
      <hardwareInterface>hardware_interface/EffortJointInterface</hardwareInterface>
      <!--hardware_interface/-->
      <mechanicalReduction>6</mechanicalReduction>
    </actuator>
  </transmission>
  <gazebo reference="RL_hip">
    <material>Gazebo/DarkGrey</material>
  </gazebo>
  <!-- <gazebo reference="FR_hip">
    <material>Gazebo/DarkGrey</material>
  </gazebo> -->
  <gazebo reference="RR_hip">
    <material>Gazebo/DarkGrey</material>
  </gazebo>
  <!-- <gazebo reference="FL_hip">
    <material>Gazebo/DarkGrey</material>
  </gazebo> -->
  <gazebo>
    <plugin filename="libgazebo_ros_control.so" name="gazebo_ros_control">
      <robotNamespace>/quadruped</robotNamespace>
    </plugin>
  </gazebo>
</robot>
