<?xml version="1.0" encoding="utf-8"?>
<robot name="quadruped_robot" xmlns:xacro="http://ros.org/wiki/xacro">

<!-- RIGHT BACK MOTOR -->

    <xacro:macro name="right_motor" params="link_prefix joint_xyz joint_rpy">
      <link
    name="${link_prefix}_motor">
    <inertial>
      <origin
        xyz="2.4016E-06 0.00012687 -0.01825"
        rpy="0 0 0" />
      <mass
        value="1.7" />
      <inertia
        ixx="0.0011015"
        ixy="-2.2115E-20"
        ixz="-4.7092E-20"
        iyy="0.0011135"
        iyz="-7.75E-06"
        izz="0.0018907" />
    </inertial>
    <visual>
      <origin
        xyz="0 0 0"
        rpy="0 0 0" />
      <geometry>
        <mesh
          filename="package://quadruped_robot/meshes/left_back_motor.STL" />
      </geometry>
      <material
        name="">
        <color
          rgba="0.098039 0.098039 0.098039 1" />
      </material>
    </visual>
    <collision>
      <origin
        xyz="0 0 0"
        rpy="0 0 0" />
      <geometry>
        <mesh
          filename="package://quadruped_robot/meshes/left_back_motor.STL" />
      </geometry>
    </collision>
  </link>
  <joint
    name="body_${link_prefix}_motor"
    type="fixed">
    <origin
      xyz="${joint_xyz}"
      rpy="${joint_rpy}" />
    <parent
      link="trunk" />
    <child
      link="${link_prefix}_motor" />
    <axis
      xyz="0 0 0" />
  </joint>
  </xacro:macro>


  <!-- LEFT HIP -->
  <xacro:macro name="right_hip" params="link_prefix joint_xyz joint_rpy">
  <link
    name="${link_prefix}_hip">
    <inertial>
      <origin
        xyz="-0.0029169 0.00012334 -0.001118"
        rpy="0 0 0" />
      <mass
        value="1.15" />
      <inertia
        ixx="0.00194402199468823"
        ixy="-7.74995368724056E-06"
        ixz="2.20326276361798E-11"
        iyy="0.00113022776843808"
        iyz="5.94322688269652E-11"
        izz="0.00115440199269891" />
    </inertial>
    <visual>
      <origin
        xyz="0 0 0"
        rpy="0 0 0" />
      <geometry>
        <mesh
          filename="package://quadruped_robot/meshes/left_back_leg.STL" />
      </geometry>
      <material
        name="">
        <color
          rgba="1 0.93725 0.13725 1" />
      </material>
    </visual>
    <collision>
      <origin
        xyz="0 0 0"
        rpy="0 0 0" />
      <geometry>
        <mesh
          filename="package://quadruped_robot/meshes/left_back_leg.STL" />
      </geometry>
    </collision>
  </link>
  <joint
    name="${link_prefix}_hip_joint"
    type="revolute">
    <origin
      xyz="${joint_xyz}"
      rpy="${joint_rpy}" />
    <parent
      link="${link_prefix}_motor" />
    <child
      link="${link_prefix}_hip" />
    <axis
      xyz="0 0 -1" />
    <limit
      lower="-0.78"
      upper="0.78"
      effort="50"
      velocity="30" />
    <!-- <dynamics damping = "0.5" friction = "0.1"/> -->
  </joint>
  </xacro:macro>

  <!--  RIGHT THIGH -->
  <xacro:macro name="right_thigh" params="link_prefix joint_xyz joint_rpy">
  <link
    name="${link_prefix}_thigh">
    <inertial>
      <origin
        xyz="-0.00011894 0.010505 0.036923"
        rpy="0 0 0" />
      <mass
        value="0.3" />
      <inertia
        ixx="0.0025944"
        ixy="2.612E-05"
        ixz="4.1998E-06"
        iyy="0.0012986"
        iyz="1.2724E-05"
        izz="0.0035306" />
    </inertial>
    <visual>
      <origin
        xyz="0 0 0"
        rpy="0 0 0" />
      <geometry>
        <mesh
          filename="package://quadruped_robot/meshes/left_back_hip.STL" />
      </geometry>
      <material
        name="">
        <color
          rgba="1 0.93725 0.13725 1" />
      </material>
    </visual>
    <collision>
      <origin
        xyz="0 0 0"
        rpy="0 0 0" />
      <geometry>
        <mesh
          filename="package://quadruped_robot/meshes/left_back_hip.STL" />
      </geometry>
    </collision>
  </link>
  <joint
    name="${link_prefix}_thigh_joint"
    type="revolute">
    <origin
      xyz="${joint_xyz}"
      rpy="${joint_rpy}"/>
    <parent
      link="${link_prefix}_hip" />
    <child
      link="${link_prefix}_thigh" />
    <axis
      xyz="0 0 -1" />
    <limit
      lower="-1.31"
      upper="1.31"
      effort="50"
      velocity="30" />
    <!-- <dynamics damping = "0.5" friction = "0.1"/> -->
  </joint>
  </xacro:macro>


  <!-- LEFT CALF -->
  <xacro:macro name="right_calf" params="link_prefix joint_xyz joint_rpy">
  <link
    name="${link_prefix}_calf">
    <inertial>
      <origin
        xyz="0.003150209581748 0.0608714249947071 0.0130084906327194"
        rpy="0 0 0" />
      <mass
        value="0.1" />
      <inertia
        ixx="0.0"
        ixy="0.0"
        ixz="0.0"
        iyy="0.0"
        iyz="0.0"
        izz="0.0" />
    </inertial>
    <visual>
      <origin
        xyz="0 0 0"
        rpy="0 0 0" />
      <geometry>
        <mesh
          filename="package://quadruped_robot/meshes/left_back_calf.STL" />
      </geometry>
      <material
        name="">
        <color
          rgba="0.101960784313725 0.101960784313725 0.101960784313725 1" />
      </material>
    </visual>
    <collision>
      <origin
        xyz="0 0 0"
        rpy="0 0 0" />
      <geometry>
        <mesh
          filename="package://quadruped_robot/meshes/left_back_calf.STL" />
      </geometry>
    </collision>
  </link>
  <joint
    name="${link_prefix}_calf_joint"
    type="revolute">
    <origin
      xyz="${joint_xyz}"
      rpy="${joint_rpy}"/>
    <parent
      link="${link_prefix}_thigh" />
    <child
      link="${link_prefix}_calf" />
    <axis
      xyz="0 0 -1" />
    <limit
      lower="-2.6"
      upper="2.6"
      effort="50"
      velocity="30" />
    <!-- <dynamics damping = "0.5" friction = "0.1"/> -->
  </joint>
  <link
    name="${link_prefix}_foot">
    <inertial>
      <origin
        xyz="2.67734406894649E-07 -0.0143807830353894 -1.27018434094295E-05"
        rpy="0 0 0" />
      <mass
        value="0.04" />
      <!-- <mass
        value="50" /> -->
      <inertia
        ixx="1.41888786495424E-05"
        ixy="-2.90568059491003E-10"
        ixz="-4.06238332327928E-11"
        iyy="8.65121074865133E-06"
        iyz="3.97669015260362E-09"
        izz="1.41178031393142E-05" />
    </inertial>
    <visual>
      <origin
        xyz="0 0 0"
        rpy="0 0 0" />
      <geometry>
        <mesh
          filename="package://quadruped_robot/meshes/left_back_foot.STL" />
      </geometry>
      <material
        name="">
        <color
          rgba="0.298039215686275 0.298039215686275 0.298039215686275 1" />
      </material>
    </visual>
    <collision>
      <origin
        xyz="0 0 0"
        rpy="0 0 0" />
      <geometry>
        <mesh
          filename="package://quadruped_robot/meshes/left_back_foot.STL" />
      </geometry>
    </collision>
  </link>
  <joint
    name="${link_prefix}_foot_fixed"
    type="fixed">
    <origin
      xyz="0.003139 0.17761 0.013"
      rpy="0 0 3.1416" />
    <parent
      link="${link_prefix}_calf" />
    <child
      link="${link_prefix}_foot" />
    <axis
      xyz="0 0 0" />
  <dynamics friction = "1000"/>
  </joint>
  </xacro:macro>

</robot>